Workbook

Sheet Raw Releases
A1: Raw Releases — every USD High/Medium release with numeric actual+forecast in the events archive (the exact universe fx_strict_battery.py computes z on). One block per release title, oldest to newest.
A2: Stats for a title are computed ONLY from rows above it within its own block (expanding, prior events only).
A4: ADP Employment Change (137 events)
A5: Date | B5: Impact | C5: Forecast | D5: Actual
A6: 42011 | B6: Medium | C6: 226 | D6: 241
A7: 42039 | B7: Medium | C7: 225 | D7: 213
A8: 42067 | B8: Medium | C8: 220 | D8: 212
A9: 42095 | B9: Medium | C9: 225 | D9: 189
A10: 42130 | B10: Medium | C10: 200 | D10: 169
A11: 42158 | B11: Medium | C11: 200 | D11: 201
A12: 42186 | B12: Medium | C12: 218 | D12: 237
A13: 42221 | B13: Medium | C13: 215 | D13: 185
A14: 42249 | B14: Medium | C14: 201 | D14: 190
A15: 42277 | B15: Medium | C15: 194 | D15: 200
A16: 42312 | B16: Medium | C16: 180 | D16: 182
A17: 42340 | B17: Medium | C17: 190 | D17: 217
... A142: 46239 | B142: Medium | C142: 70 | D142: 44
A143: API Crude Oil Stock Change (288 events)
A144: Date | B144: Impact | C144: Forecast | D144: Actual
A145: 43096 | B145: Medium | C145: -3.8 | D145: -6
A146: 43109 | B146: Medium | C146: -3.9 | D146: -11.19
A147: 43123 | B147: Medium | C147: -1.6 | D147: 4.755
A148: 43158 | B148: Medium | C148: 2.7 | D148: 0.933
A149: 43186 | B149: Medium | C149: 1 | D149: 5.321
A150: 43207 | B150: Medium | C150: -2.1 | D150: -1.047
A151: 43235 | B151: Medium | C151: -2 | D151: 4.854
A152: 43242 | B152: Medium | C152: -3 | D152: -1.3
A153: 43263 | B153: Medium | C153: -2.8 | D153: -0.73
A154: 43375 | B154: Medium | C154: 1.5 | D154: 0.907
A155: 43452 | B155: Medium | C155: -2.45 | D155: 3.45
A156: 43473 | B156: Medium | C156: -3.4 | D156: -6.27
... A432: 46238 | B432: Medium | C432: -2 | D432: 2.69
A433: Average Hourly Earnings MoM (56 events)
A434: Date | B434: Impact | C434: Forecast | D434: Actual
A435: 44533 | B435: Medium | C435: 0.4 | D435: 0.3
A436: 44568 | B436: Medium | C436: 0.4 | D436: 0.6
A437: 44596 | B437: Medium | C437: 0.5 | D437: 0.7
A438: 44624 | B438: Medium | C438: 0.5 | D438: 0
A439: 44652 | B439: Medium | C439: 0.4 | D439: 0.4
A440: 44687 | B440: Medium | C440: 0.4 | D440: 0.3
...

Sheet Z-Score Calc
A1: Z-Score Calc — live Excel formulas for every row (min_periods=20, std floored at 1e-12, z clipped to +/-8, trigger |z| >= 0.5, direction = sign(z)). | M1: z parameters (from fx_strict_battery.py)
A2: Stats use only rows ABOVE the current row within the same title block (no lookahead, mirrors pandas expanding(...).shift(1)). Rows 1-20 of each block have no z (insufficient history). | M2: min prior events | N2: 20
M3: std floor | N3: 1e-12
A4: ADP Employment Change (137 events) | M4: z clip | N4: +-8.0
A5: Date | B5: Impact | C5: Forecast | D5: Actual | E5: Surprise | F5: Prior | G5: Trail mean | H5: Trail std | I5: z | J5: Trigger | K5: Direction | M5: trigger |z| >= | N5: 0.5
A6: 42011 | B6: Medium | C6: 226 | D6: 241 | E6: =D6-C6 | F6: =ROW()-ROW($A$6) | M6: stats window | N6: expanding, prior rows only (shift(1))
A7: 42039 | B7: Medium | C7: 225 | D7: 213 | E7: =D7-C7 | F7: =ROW()-ROW($A$6) | M7: 1-pip RT cost (frac) | N7: 7.9464792e-05
A8: 42067 | B8: Medium | C8: 220 | D8: 212 | E8: =D8-C8 | F8: =ROW()-ROW($A$6)
A9: 42095 | B9: Medium | C9: 225 | D9: 189 | E9: =D9-C9 | F9: =ROW()-ROW($A$6)
A10: 42130 | B10: Medium | C10: 200 | D10: 169 | E10: =D10-C10 | F10: =ROW()-ROW($A$6)
A11: 42158 | B11: Medium | C11: 200 | D11: 201 | E11: =D11-C11 | F11: =ROW()-ROW($A$6)
A12: 42186 | B12: Medium | C12: 218 | D12: 237 | E12: =D12-C12 | F12: =ROW()-ROW($A$6)
A13: 42221 | B13: Medium | C13: 215 | D13: 185 | E13: =D13-C13 | F13: =ROW()-ROW($A$6)
A14: 42249 | B14: Medium | C14: 201 | D14: 190 | E14: =D14-C14 | F14: =ROW()-ROW($A$6)
A15: 42277 | B15: Medium | C15: 194 | D15: 200 | E15: =D15-C15 | F15: =ROW()-ROW($A$6)
A16: 42312 | B16: Medium | C16: 180 | D16: 182 | E16: =D16-C16 | F16: =ROW()-ROW($A$6)
A17: 42340 | B17: Medium | C17: 190 | D17: 217 | E17: =D17-C17 | F17: =ROW()-ROW($A$6)
A18: 42375 | B18: Medium | C18: 192 | D18: 257 | E18: =D18-C18 | F18: =ROW()-ROW($A$6)
A19: 42403 | B19: Medium | C19: 195 | D19: 205 | E19: =D19-C19 | F19: =ROW()-ROW($A$6)
... A25: 42585 | B25: Medium | C25: 170 | D25: 179 | E25: =D25-C25 | F25: =ROW()-ROW($A$6)
A26: 42613 | B26: Medium | C26: 175 | D26: 177 | E26: =D26-C26 | F26: =ROW()-ROW($A$6) | G26: =AVERAGE($E$6:$E$25) | H26: =STDEV($E$6:$E$25) | I26: =MIN(MAX((E26-G26)/IF(H26>1e-12,H26,NA()),-8.0),8.0) | J26: =IF(NOT(ISNA(I26)),IF(ABS(I26)>=0.5,"TRIGGER",""),"") | K26: =IF(J26="TRIGGER",IF(I26>0,"LONG","SHORT"),"")
A27: 42648 | B27: Medium | C27: 169 | D27: 154 | E27: =D27-C27 | F27: =ROW()-ROW($A$6) | G27: =AVERAGE($E$6:$E$26) | H27: =STDEV($E$6:$E$26) | I27: =MIN(MAX((E27-G27)/IF(H27>1e-12,H27,NA()),-8.0),8.0) | J27: =IF(NOT(ISNA(I27)),IF(ABS(I27)>=0.5,"TRIGGER",""),"") | K27: =IF(J27="TRIGGER",IF(I27>0,"LONG","SHORT"),"")
A28: 42676 | B28: Medium | C28: 165 | D28: 147 | E28: =D28-C28 | F28: =ROW()-ROW($A$6) | G28: =AVERAGE($E$6:$E$27) | H28: =STDEV($E$6:$E$27) | I28: =MIN(MAX((E28-G28)/IF(H28>1e-12,H28,NA()),-8.0),8.0) | J28: =IF(NOT(ISNA(I28)),IF(ABS(I28)>=0.5,"TRIGGER",""),"") | K28: =IF(J28="TRIGGER",IF(I28>0,"LONG","SHORT"),"")
A29: 42704 | B29: Medium | C29: 165 | D29: 216 | E29: =D29-C29 | F29: =ROW()-ROW($A$6) | G29: =AVERAGE($E$6:$E$28) | H29: =STDEV($E$6:$E$28) | I29: =MIN(MAX((E29-G29)/IF(H29>1e-12,H29,NA()),-8.0),8.0) | J29: =IF(NOT(ISNA(I29)),IF(ABS(I29)>=0.5,"TRIGGER",""),"") | K29: =IF(J29="TRIGGER",IF(I29>0,"LONG","SHORT"),"")
A30: 42740 | B30: Medium | C30: 170 | D30: 153 | E30: =D30-C30 | F30: =ROW()-ROW($A$6) | G30: =AVERAGE($E$6:$E$29) | H30: =STDEV($E$6:$E$29) | I30: =MIN(MAX((E30-G30)/IF(H30>1e-12,H30,NA()),-8.0),8.0) | J30: =IF(NOT(ISNA(I30)),IF(ABS(I30)>=0.5,"TRIGGER",""),"") | K30: =IF(J30="TRIGGER",IF(I30>0,"LONG","SHORT"),"")
A31: 42767 | B31: Medium | C31: 165 | D31: 246 | E31: =D31-C31 | F31: =ROW()-ROW($A$6) | G31: =AVERAGE($E$6:$E$30) | H31: =STDEV($E$6:$E$30) | I31: =MIN(MAX((E31-G31)/IF(H31>1e-12,H31,NA()),-8.0),8.0) | J31: =IF(NOT(ISNA(I31)),IF(ABS(I31)>=0.5,"TRIGGER",""),"") | K31: =IF(J31="TRIGGER",IF(I31>0,"LONG","SHORT"),"")
A32: 42802 | B32: Medium | C32: 190 | D32: 298 | E32: =D32-C32 | F32: =ROW()-ROW($A$6) | G32: =AVERAGE($E$6:$E$31) | H32: =STDEV($E$6:$E$31) | I32: =MIN(MAX((E32-G32)/IF(H32>1e-12,H32,NA()),-8.0),8.0) | J32: =IF(NOT(ISNA(I32)),IF(ABS(I32)>=0.5,"TRIGGER",""),"") | K32: =IF(J32="TRIGGER",IF(I32>0,"LONG","SHORT"),"")
A33: 42830 | B33: Medium | C33: 187 | D33: 263 | E33: =D33-C33 | F33: =ROW()-ROW($A$6) | G33: =AVERAGE($E$6:$E$32) | H33: =STDEV($E$6:$E$32) | I33: =MIN(MAX((E33-G33)/IF(H33>1e-12,H33,NA()),-8.0),8.0) | J33: =IF(NOT(ISNA(I33)),IF(ABS(I33)>=0.5,"TRIGGER",""),"") | K33: =IF(J33="TRIGGER",IF(I33>0,"LONG","SHORT"),"")
A34: 42858 | B34: Medium | C34: 175 | D34: 177 | E34: =D34-C34 | F34: =ROW()-ROW($A$6) | G34: =AVERAGE($E$6:$E$33) | H34: =STDEV($E$6:$E$33) | I34: =MIN(MAX((E34-G34)/IF(H34>1e-12,H34,NA()),-8.0),8.0) | J34: =IF(NOT(ISNA(I34)),IF(ABS(I34)>=0.5,"TRIGGER",""),"") | K34: =IF(J34="TRIGGER",IF(I34>0,"LONG","SHORT"),"")
A35: 42887 | B35: Medium | C35: 185 | D35: 253 | E35: =D35-C35 | F35: =ROW()-ROW($A$6) | G35: =AVERAGE($E$6:$E$34) | H35: =STDEV($E$6:$E$34) | I35: =MIN(MAX((E35-G35)/IF(H35>1e-12,H35,NA()),-8.0),8.0) | J35: =IF(NOT(ISNA(I35)),IF(ABS(I35)>=0.5,"TRIGGER",""),"") | K35: =IF(J35="TRIGGER",IF(I35>0,"LONG","SHORT"),"")
A36: 42922 | B36: Medium | C36: 185 | D36: 158 | E36: =D36-C36 | F36: =ROW()-ROW($A$6) | G36: =AVERAGE($E$6:$E$35) | H36: =STDEV($E$6:$E$35) | I36: =MIN(MAX((E36-G36)/IF(H36>1e-12,H36,NA()),-8.0),8.0) | J36: =IF(NOT(ISNA(I36)),IF(ABS(I36)>=0.5,"TRIGGER",""),"") | K36: =IF(J36="TRIGGER",IF(I36>0,"LONG","SHORT"),"")
A37: 42949 | B37: Medium | C37: 185 | D37: 178 | E37: =D37-C37 | F37: =ROW()-ROW($A$6) | G37: =AVERAGE($E$6:$E$36) | H37: =STDEV($E$6:$E$36) | I37: =MIN(MAX((E37-G37)/IF(H37>1e-12,H37,NA()),-8.0),8.0) | J37: =IF(NOT(ISNA(I37)),IF(ABS(I37)>=0.5,"TRIGGER",""),"") | K37: =IF(J37="TRIGGER",IF(I37>0,"LONG","SHORT"),"")
A38: 42977 | B38: Medium | C38: 183 | D38: 237 | E38: =D38-C38 | F38: =ROW()-ROW($A$6) | G38: =AVERAGE($E$6:$E$37) | H38: =STDEV($E$6:$E$37) | I38: =MIN(MAX((E38-G38)/IF(H38>1e-12,H38,NA()),-8.0),8.0) | J38: =IF(NOT(ISNA(I38)),IF(ABS(I38)>=0.5,"TRIGGER",""),"") | K38: =IF(J38="TRIGGER",IF(I38>0,"LONG","SHORT"),"")
A39: 43012 | B39: Medium | C39: 125 | D39: 135 | E39: =D39-C39 | F39: =ROW()-ROW($A$6) | G39: =AVERAGE($E$6:$E$38) | H39: =STDEV($E$6:$E$38) | I39: =MIN(MAX((E39-G39)/IF(H39>1e-12,H39,NA()),-8.0),8.0) | J39: =IF(NOT(ISNA(I39)),IF(ABS(I39)>=0.5,"TRIGGER",""),"") | K39: =IF(J39="TRIGGER",IF(I39>0,"LONG","SHORT"),"")
A40: 43040 | B40: Medium | C40: 200 | D40: 235 | E40: =D40-C40 | F40: =ROW()-ROW($A$6) | G40: =AVERAGE($E$6:$E$39) | H40: =STDEV($E$6:$E$39) | I40: =MIN(MAX((E40-G40)/IF(H40>1e-12,H40,NA()),-8.0),8.0) | J40: =IF(NOT(ISNA(I40)),IF(ABS(I40)>=0.5,"TRIGGER",""),"") | K40: =IF(J40="TRIGGER",IF(I40>0,"LONG","SHORT"),"")
A41: 43075 | B41: Medium | C41: 185 | D41: 190 | E41: =D41-C41 | F41: =ROW()-ROW($A$6) | G41: =AVERAGE($E$6:$E$40) | H41: =STDEV($E$6:$E$40) | I41: =MIN(MAX((E41-G41)/IF(H41>1e-12,H41,NA()),-8.0),8.0) | J41: =IF(NOT(ISNA(I41)),IF(ABS(I41)>=0.5,"TRIGGER",""),"") | K41: =IF(J41="TRIGGER",IF(I41>0,"LONG","SHORT"),"")
A42: 43104 | B42: Medium | C42: 190 | D42: 250 | E42: =D42-C42 | F42: =ROW()-ROW($A$6) | G42: =AVERAGE($E$6:$E$41) | H42: =STDEV($E$6:$E$41) | I42: =MIN(MAX((E42-G42)/IF(H42>1e-12,H42,NA()),-8.0),8.0) | J42: =IF(NOT(ISNA(I42)),IF(ABS(I42)>=0.5,"TRIGGER",""),"") | K42: =IF(J42="TRIGGER",IF(I42>0,"LONG","SHORT"),"")
A43: 43131 | B43: Medium | C43: 186 | D43: 234 | E43: =D43-C43 | F43: =ROW()-ROW($A$6) | G43: =AVERAGE($E$6:$E$42) | H43: =STDEV($E$6:$E$42) | I43: =MIN(MAX((E43-G43)/IF(H43>1e-12,H43,NA()),-8.0),8.0) | J43: =IF(NOT(ISNA(I43)),IF(ABS(I43)>=0.5,"TRIGGER",""),"") | K43: =IF(J43="TRIGGER",IF(I43>0,"LONG","SHORT"),"")
A44: 43166 | B44: Medium | C44: 195 | D44: 235 | E44: =D44-C44 | F44: =ROW()-ROW($A$6) | G44: =AVERAGE($E$6:$E$43) | H44: =STDEV($E$6:$E$43) | I44: =MIN(MAX((E44-G44)/IF(H44>1e-12,H44,NA()),-8.0),8.0) | J44: =IF(NOT(ISNA(I44)),IF(ABS(I44)>=0.5,"TRIGGER",""),"") | K44: =IF(J44="TRIGGER",IF(I44>0,"LONG","SHORT"),"")
A45: 43194 | B45: Medium | C45: 208 | D45: 241 | E45: =D45-C45 | F45: =ROW()-ROW($A$6) | G45: =AVERAGE($E$6:$E$44) | H45: =STDEV($E$6:$E$44) | I45: =MIN(MAX((E45-G45)/IF(H45>1e-12,H45,NA()),-8.0),8.0) | J45: =IF(NOT(ISNA(I45)),IF(ABS(I45)>=0.5,"TRIGGER",""),"") | K45: =IF(J45="TRIGGER",IF(I45>0,"LONG","SHORT"),"")
...

Sheet Trigger Check
A1: Trigger Check — formula-computed trigger (live, from Z-Score Calc) vs the strategy's reported trigger (reproduced from fx_strict_battery.py, verified to its saved stats). Any mismatch between B and C is a bug. | M1: 1-pip RT cost (frac) | N1: 7.9464792e-05
A2: Mismatch means the live spreadsheet no longer reproduces the strategy — check the z params or data. | M2: cost cell ref (K col) | N2: $N$1
A4: ADP Employment Change (137 events)
A5: Date | B5: Formula trigger | C5: Reported trigger | D5: z (reported) | E5: Direction | F5: Period | G5: Event close | H5: Next close | I5: Raw move % (formula) | J5: Net % (reported) | K5: Net % (formula)
A6: 42011 | B6: ='Z-Score Calc'!J6 | F6: IS | I6: =IF(AND(ISNUMBER(G6),ISNUMBER(H6)),H6/G6-1,"") | K6: =IF(ISNA(B6),"",IF(B6="TRIGGER",IF(ISNUMBER(I6),SIGN('Z-Score Calc'!I6)*I6-$N$1,""),""))
A7: 42039 | B7: ='Z-Score Calc'!J7 | F7: IS | I7: =IF(AND(ISNUMBER(G7),ISNUMBER(H7)),H7/G7-1,"") | K7: =IF(ISNA(B7),"",IF(B7="TRIGGER",IF(ISNUMBER(I7),SIGN('Z-Score Calc'!I7)*I7-$N$1,""),""))
A8: 42067 | B8: ='Z-Score Calc'!J8 | F8: IS | I8: =IF(AND(ISNUMBER(G8),ISNUMBER(H8)),H8/G8-1,"") | K8: =IF(ISNA(B8),"",IF(B8="TRIGGER",IF(ISNUMBER(I8),SIGN('Z-Score Calc'!I8)*I8-$N$1,""),""))
A9: 42095 | B9: ='Z-Score Calc'!J9 | F9: IS | I9: =IF(AND(ISNUMBER(G9),ISNUMBER(H9)),H9/G9-1,"") | K9: =IF(ISNA(B9),"",IF(B9="TRIGGER",IF(ISNUMBER(I9),SIGN('Z-Score Calc'!I9)*I9-$N$1,""),""))
A10: 42130 | B10: ='Z-Score Calc'!J10 | F10: IS | I10: =IF(AND(ISNUMBER(G10),ISNUMBER(H10)),H10/G10-1,"") | K10: =IF(ISNA(B10),"",IF(B10="TRIGGER",IF(ISNUMBER(I10),SIGN('Z-Score Calc'!I10)*I10-$N$1,""),""))
A11: 42158 | B11: ='Z-Score Calc'!J11 | F11: IS | I11: =IF(AND(ISNUMBER(G11),ISNUMBER(H11)),H11/G11-1,"") | K11: =IF(ISNA(B11),"",IF(B11="TRIGGER",IF(ISNUMBER(I11),SIGN('Z-Score Calc'!I11)*I11-$N$1,""),""))
A12: 42186 | B12: ='Z-Score Calc'!J12 | F12: IS | I12: =IF(AND(ISNUMBER(G12),ISNUMBER(H12)),H12/G12-1,"") | K12: =IF(ISNA(B12),"",IF(B12="TRIGGER",IF(ISNUMBER(I12),SIGN('Z-Score Calc'!I12)*I12-$N$1,""),""))
A13: 42221 | B13: ='Z-Score Calc'!J13 | F13: IS | I13: =IF(AND(ISNUMBER(G13),ISNUMBER(H13)),H13/G13-1,"") | K13: =IF(ISNA(B13),"",IF(B13="TRIGGER",IF(ISNUMBER(I13),SIGN('Z-Score Calc'!I13)*I13-$N$1,""),""))
A14: 42249 | B14: ='Z-Score Calc'!J14 | F14: IS | I14: =IF(AND(ISNUMBER(G14),ISNUMBER(H14)),H14/G14-1,"") | K14: =IF(ISNA(B14),"",IF(B14="TRIGGER",IF(ISNUMBER(I14),SIGN('Z-Score Calc'!I14)*I14-$N$1,""),""))
A15: 42277 | B15: ='Z-Score Calc'!J15 | F15: IS | I15: =IF(AND(ISNUMBER(G15),ISNUMBER(H15)),H15/G15-1,"") | K15: =IF(ISNA(B15),"",IF(B15="TRIGGER",IF(ISNUMBER(I15),SIGN('Z-Score Calc'!I15)*I15-$N$1,""),""))
A16: 42312 | B16: ='Z-Score Calc'!J16 | F16: IS | I16: =IF(AND(ISNUMBER(G16),ISNUMBER(H16)),H16/G16-1,"") | K16: =IF(ISNA(B16),"",IF(B16="TRIGGER",IF(ISNUMBER(I16),SIGN('Z-Score Calc'!I16)*I16-$N$1,""),""))
A17: 42340 | B17: ='Z-Score Calc'!J17 | F17: IS | I17: =IF(AND(ISNUMBER(G17),ISNUMBER(H17)),H17/G17-1,"") | K17: =IF(ISNA(B17),"",IF(B17="TRIGGER",IF(ISNUMBER(I17),SIGN('Z-Score Calc'!I17)*I17-$N$1,""),""))
... A25: 42585 | B25: ='Z-Score Calc'!J25 | F25: IS | I25: =IF(AND(ISNUMBER(G25),ISNUMBER(H25)),H25/G25-1,"") | K25: =IF(ISNA(B25),"",IF(B25="TRIGGER",IF(ISNUMBER(I25),SIGN('Z-Score Calc'!I25)*I25-$N$1,""),""))
A26: 42613 | B26: ='Z-Score Calc'!J26 | D26: 0.026310297 | F26: IS | G26: 103.302 | H26: 103.258 | I26: =IF(AND(ISNUMBER(G26),ISNUMBER(H26)),H26/G26-1,"") | J26: -0.00050538798 | K26: =IF(ISNA(B26),"",IF(B26="TRIGGER",IF(ISNUMBER(I26),SIGN('Z-Score Calc'!I26)*I26-$N$1,""),""))
A27: 42648 | B27: ='Z-Score Calc'!J27 | C27: TRIGGER | D27: -0.68027139 | E27: SHORT | F27: IS | G27: 103.46 | H27: 103.765 | I27: =IF(AND(ISNUMBER(G27),ISNUMBER(H27)),H27/G27-1,"") | J27: -0.003027467 | K27: =IF(ISNA(B27),"",IF(B27="TRIGGER",IF(ISNUMBER(I27),SIGN('Z-Score Calc'!I27)*I27-$N$1,""),""))
A28: 42676 | B28: ='Z-Score Calc'!J28 | C28: TRIGGER | D28: -0.78443148 | E28: SHORT | F28: IS | G28: 104.092 | H28: 103.378 | I28: =IF(AND(ISNUMBER(G28),ISNUMBER(H28)),H28/G28-1,"") | J28: 0.0067798952 | K28: =IF(ISNA(B28),"",IF(B28="TRIGGER",IF(ISNUMBER(I28),SIGN('Z-Score Calc'!I28)*I28-$N$1,""),""))
A29: 42704 | B29: ='Z-Score Calc'!J29 | C29: TRIGGER | D29: 2.1744117 | E29: LONG | F29: IS | G29: 112.47 | H29: 114.694 | I29: =IF(AND(ISNUMBER(G29),ISNUMBER(H29)),H29/G29-1,"") | J29: 0.019694688 | K29: =IF(ISNA(B29),"",IF(B29="TRIGGER",IF(ISNUMBER(I29),SIGN('Z-Score Calc'!I29)*I29-$N$1,""),""))
A30: 42740 | B30: ='Z-Score Calc'!J30 | C30: TRIGGER | D30: -0.75003217 | E30: SHORT | F30: IS | G30: 117.113 | H30: 115.265 | I30: =IF(AND(ISNUMBER(G30),ISNUMBER(H30)),H30/G30-1,"") | J30: 0.015700163 | K30: =IF(ISNA(B30),"",IF(B30="TRIGGER",IF(ISNUMBER(I30),SIGN('Z-Score Calc'!I30)*I30-$N$1,""),""))
A31: 42767 | B31: ='Z-Score Calc'!J31 | C31: TRIGGER | D31: 3.1877525 | E31: LONG | F31: IS | G31: 112.743 | H31: 113.311 | I31: =IF(AND(ISNUMBER(G31),ISNUMBER(H31)),H31/G31-1,"") | J31: 0.0049585492 | K31: =IF(ISNA(B31),"",IF(B31="TRIGGER",IF(ISNUMBER(I31),SIGN('Z-Score Calc'!I31)*I31-$N$1,""),""))
A32: 42802 | B32: ='Z-Score Calc'!J32 | C32: TRIGGER | D32: 3.5652321 | E32: LONG | F32: IS | G32: 113.926 | H32: 114.411 | I32: =IF(AND(ISNUMBER(G32),ISNUMBER(H32)),H32/G32-1,"") | J32: 0.0041776898 | K32: =IF(ISNA(B32),"",IF(B32="TRIGGER",IF(ISNUMBER(I32),SIGN('Z-Score Calc'!I32)*I32-$N$1,""),""))
A33: 42830 | B33: ='Z-Score Calc'!J33 | C33: TRIGGER | D33: 1.9496656 | E33: LONG | F33: IS | G33: 110.381 | H33: 110.897 | I33: =IF(AND(ISNUMBER(G33),ISNUMBER(H33)),H33/G33-1,"") | J33: 0.0045953115 | K33: =IF(ISNA(B33),"",IF(B33="TRIGGER",IF(ISNUMBER(I33),SIGN('Z-Score Calc'!I33)*I33-$N$1,""),""))
A34: 42858 | B34: ='Z-Score Calc'!J34 | D34: -0.23386099 | F34: IS | G34: 112.783 | H34: 112.537 | I34: =IF(AND(ISNUMBER(G34),ISNUMBER(H34)),H34/G34-1,"") | J34: 0.0021016669 | K34: =IF(ISNA(B34),"",IF(B34="TRIGGER",IF(ISNUMBER(I34),SIGN('Z-Score Calc'!I34)*I34-$N$1,""),""))
A35: 42887 | B35: ='Z-Score Calc'!J35 | C35: TRIGGER | D35: 1.6099322 | E35: LONG | F35: IS | G35: 111.437 | H35: 110.463 | I35: =IF(AND(ISNUMBER(G35),ISNUMBER(H35)),H35/G35-1,"") | J35: -0.0088198208 | K35: =IF(ISNA(B35),"",IF(B35="TRIGGER",IF(ISNUMBER(I35),SIGN('Z-Score Calc'!I35)*I35-$N$1,""),""))
A36: 42922 | B36: ='Z-Score Calc'!J36 | C36: TRIGGER | D36: -1.0644308 | E36: SHORT | F36: IS | G36: 113.149 | H36: 113.985 | I36: =IF(AND(ISNUMBER(G36),ISNUMBER(H36)),H36/G36-1,"") | J36: -0.0074679395 | K36: =IF(ISNA(B36),"",IF(B36="TRIGGER",IF(ISNUMBER(I36),SIGN('Z-Score Calc'!I36)*I36-$N$1,""),""))
A37: 42949 | B37: ='Z-Score Calc'!J37 | D37: -0.4857748 | F37: IS | G37: 110.757 | H37: 109.9 | I37: =IF(AND(ISNUMBER(G37),ISNUMBER(H37)),H37/G37-1,"") | J37: 0.0076582153 | K37: =IF(ISNA(B37),"",IF(B37="TRIGGER",IF(ISNUMBER(I37),SIGN('Z-Score Calc'!I37)*I37-$N$1,""),""))
A38: 42977 | B38: ='Z-Score Calc'!J38 | C38: TRIGGER | D38: 1.1995599 | E38: LONG | F38: IS | G38: 110.46 | H38: 110.129 | I38: =IF(AND(ISNUMBER(G38),ISNUMBER(H38)),H38/G38-1,"") | J38: -0.0030760363 | K38: =IF(ISNA(B38),"",IF(B38="TRIGGER",IF(ISNUMBER(I38),SIGN('Z-Score Calc'!I38)*I38-$N$1,""),""))
A39: 43012 | B39: ='Z-Score Calc'!J39 | D39: -0.045515359 | F39: IS | G39: 112.823 | H39: 112.774 | I39: =IF(AND(ISNUMBER(G39),ISNUMBER(H39)),H39/G39-1,"") | J39: 0.00035480812 | K39: =IF(ISNA(B39),"",IF(B39="TRIGGER",IF(ISNUMBER(I39),SIGN('Z-Score Calc'!I39)*I39-$N$1,""),""))
A40: 43040 | B40: ='Z-Score Calc'!J40 | C40: TRIGGER | D40: 0.648434 | E40: LONG | F40: IS | G40: 113.65 | H40: 114.152 | I40: =IF(AND(ISNUMBER(G40),ISNUMBER(H40)),H40/G40-1,"") | J40: 0.0043375954 | K40: =IF(ISNA(B40),"",IF(B40="TRIGGER",IF(ISNUMBER(I40),SIGN('Z-Score Calc'!I40)*I40-$N$1,""),""))
A41: 43075 | B41: ='Z-Score Calc'!J41 | D41: -0.20382665 | F41: IS | G41: 112.464 | H41: 112.291 | I41: =IF(AND(ISNUMBER(G41),ISNUMBER(H41)),H41/G41-1,"") | J41: 0.0014587743 | K41: =IF(ISNA(B41),"",IF(B41="TRIGGER",IF(ISNUMBER(I41),SIGN('Z-Score Calc'!I41)*I41-$N$1,""),""))
A42: 43104 | B42: ='Z-Score Calc'!J42 | C42: TRIGGER | D42: 1.3592902 | E42: LONG | F42: IS | G42: 112.607 | H42: 112.783 | I42: =IF(AND(ISNUMBER(G42),ISNUMBER(H42)),H42/G42-1,"") | J42: 0.0014834475 | K42: =IF(ISNA(B42),"",IF(B42="TRIGGER",IF(ISNUMBER(I42),SIGN('Z-Score Calc'!I42)*I42-$N$1,""),""))
A43: 43131 | B43: ='Z-Score Calc'!J43 | C43: TRIGGER | D43: 0.97143492 | E43: LONG | F43: IS | G43: 108.732 | H43: 109.201 | I43: =IF(AND(ISNUMBER(G43),ISNUMBER(H43)),H43/G43-1,"") | J43: 0.0042338388 | K43: =IF(ISNA(B43),"",IF(B43="TRIGGER",IF(ISNUMBER(I43),SIGN('Z-Score Calc'!I43)*I43-$N$1,""),""))
A44: 43166 | B44: ='Z-Score Calc'!J44 | C44: TRIGGER | D44: 0.72219428 | E44: LONG | F44: IS | G44: 105.537 | H44: 106.186 | I44: =IF(AND(ISNUMBER(G44),ISNUMBER(H44)),H44/G44-1,"") | J44: 0.0060699845 | K44: =IF(ISNA(B44),"",IF(B44="TRIGGER",IF(ISNUMBER(I44),SIGN('Z-Score Calc'!I44)*I44-$N$1,""),""))
A45: 43194 | B45: ='Z-Score Calc'!J45 | C45: TRIGGER | D45: 0.5103638 | E45: LONG | F45: IS | G45: 106.774 | H45: 107.052 | I45: =IF(AND(ISNUMBER(G45),ISNUMBER(H45)),H45/G45-1,"") | J45: 0.0025241641 | K45: =IF(ISNA(B45),"",IF(B45="TRIGGER",IF(ISNUMBER(I45),SIGN('Z-Score Calc'!I45)*I45-$N$1,""),""))
A46: 43222 | B46: ='Z-Score Calc'!J46 | D46: -0.32543988 | F46: IS | G46: 109.827 | H46: 109.096 | I46: =IF(AND(ISNUMBER(G46),ISNUMBER(H46)),H46/G46-1,"") | J46: 0.0065764831 | K46: =IF(ISNA(B46),"",IF(B46="TRIGGER",IF(ISNUMBER(I46),SIGN('Z-Score Calc'!I46)*I46-$N$1,""),""))
A47: 43250 | B47: ='Z-Score Calc'!J47 | C47: TRIGGER | D47: -0.78308695 | E47: SHORT | F47: IS | G47: 108.712 | H47: 108.749 | I47: =IF(AND(ISNUMBER(G47),ISNUMBER(H47)),H47/G47-1,"") | J47: -0.00041983719 | K47: =IF(ISNA(B47),"",IF(B47="TRIGGER",IF(ISNUMBER(I47),SIGN('Z-Score Calc'!I47)*I47-$N$1,""),""))
A48: 43286 | B48: ='Z-Score Calc'!J48 | D48: 0.36338063 | F48: IS | G48: 110.579 | H48: 110.422 | I48: =IF(AND(ISNUMBER(G48),ISNUMBER(H48)),H48/G48-1,"") | J48: -0.0014993122 | K48: =IF(ISNA(B48),"",IF(B48="TRIGGER",IF(ISNUMBER(I48),SIGN('Z-Score Calc'!I48)*I48-$N$1,""),""))
...

Sheet Instructions
A1: USDJPY NEWS UNDER-REACTION DRIFT — the rule, from code (ground truth: E:/forex-data/scripts/fx_strict_battery.py)
A3: 1. THE RULE (plain English)
A4: - Universe: every US (currency=USD) economic release tagged High or Medium impact that has a
A5: numeric forecast AND numeric actual in the Forex Factory archive.
A6: - Surprise = actual - forecast (as printed, numeric only).
A7: - For each release title (e.g. Non Farm Payrolls) separately, compute a trailing z-score using ONLY
A8: that title's own earlier surprises: z = (surprise - mean of prior surprises) / std of prior surprises.
A9: - Needs at least 20 prior surprises of the same title (otherwise no z = no trade).
A10: - Standard deviation floored at 1e-12 (a constant-surprise title never trades).
A11: - z clipped to +/-8.
A12: - TRIGGER: |z| >= 0.5. Direction: LONG USDJPY if z > 0, SHORT USDJPY if z < 0.
A14: 2. ENTRY / EXIT — exact timing (this is where the README label is imprecise)
... A60: - Headline stats reproduce the battery's saved numbers exactly.
